Workbook

Sheet Company Information
B3: S.NO | C3: Company Name | D3: Sector | E3: Time Period | F3: Source Link (Screener)
B4: 1 | C4: Maruti Suzuki | D4: Auto | E4: FY19,FY22-FY25 | F4: https://www.screener.in/dash/
B5: 2 | C5: Tata Motors | D5: Auto | E5: FY19,FY22-FY25 | F5: https://www.screener.in/dash/
B6: 3 | C6: Mahindra & Mahindra | D6: Auto | E6: FY19,FY22-FY25 | F6: https://www.screener.in/dash/
B7: 4 | C7: Ashok Leyland | D7: Auto | E7: FY19,FY22-FY25 | F7: https://www.screener.in/dash/
B8: 5 | C8: Eicher Motors | D8: Auto | E8: FY19,FY22-FY25 | F8: https://www.screener.in/dash/
B9: 6 | C9: Bajaj Auto | D9: Auto | E9: FY19,FY22-FY25 | F9: https://www.screener.in/dash/
B10: 7 | C10: Hero Motocorp | D10: Auto | E10: FY19,FY22-FY25 | F10: https://www.screener.in/dash/
B11: 8 | C11: TVS Motors | D11: Auto | E11: FY19,FY22-FY25 | F11: https://www.screener.in/dash/
B12: 9 | C12: MRF | D12: Tyres | E12: FY19,FY22-FY25 | F12: https://www.screener.in/dash/
B13: 10 | C13: Apollo Tyres | D13: Tyres | E13: FY19,FY22-FY25 | F13: https://www.screener.in/dash/

Sheet Raw Financial Data
A1: Company | B1: Year | C1: Revenue | D1: EBITDA | E1: EBIT | F1: PAT | G1: Total Asset | H1: Total Liabilities | I1: Total Debt | J1: Current Asset | K1: Current Liabilities | L1: Invetory | M1: Shareholder Equity | N1: Intrest expeses | O1: COGS | P1: Operating Cash Flow | Q1: Capital Expenditure | R1: Free Cash Flow
A2: Maruti Suzuki | B2: 2019 | C2: 88785.8 | D2: 13720.5 | E2: 10699.7 | F2: 7649.1 | G2: 63968.7 | H2: 16859 | I2: 8 | J2: 12372.7 | K2: 14160.5 | L2: 3322.6 | M2: 47109.7 | N2: 75.9 | O2: 63494.9 | P2: 6600.9 | Q2: 4872.4 | R2: 1728.5
A3: Maruti Suzuki | B3: 2022 | C3: 90236.4 | D3: 7612.8 | E3: 4823.8 | F3: 3879.5 | G3: 4655.5 | H3: 19322 | I3: 32.9 | J3: 16793.4 | K3: 17023.5 | L3: 3532.3 | M3: 55333.5 | N3: 126.6 | O3: 70819.4 | P3: 1840.5 | Q3: 3459.3 | R3: -1618.8
A4: Maruti Suzuki | B4: 2023 | C4: 119889.4 | D4: 13335.8 | E4: 10510.1 | F4: 8211 | G4: 84596.9 | H4: 22805.6 | I4: 24.9 | J4: 11615.6 | K4: 20107.3 | L4: 4283.5 | M4: 61791.3 | N4: 187 | O4: 92079.3 | P4: 9251.4 | Q4: 6347.3 | R4: 2904.1
A5: Maruti Suzuki | B5: 2024 | C5: 146205.8 | D5: 22873.9 | E5: 17618.1 | F5: 13488.2 | G5: 115304.1 | H5: 29668.1 | I5: 67.7 | J5: 22633.8 | K5: 25951.8 | L5: 5318.1 | M5: 85636 | N5: 193.6 | O5: 107454.5 | P5: 16801.1 | Q5: 9199.9 | R5: 7601.2
A6: Maruti Suzuki | B6: 2025 | C6: 158179.1 | D6: 25422.4 | E6: 19814.2 | F6: 14500.2 | G6: 131971.2 | H6: 35731.3 | I6: 58.6 | J6: 29524.2 | K6: 30570.5 | L6: 6913.2 | M6: 96239.9 | N6: 194.2 | O6: 116796.9 | P6: 16136.2 | Q6: 10640.6 | R6: 5495.6
A7: Tata Motors | B7: 2019 | C7: 305280.69 | D7: -2021.92 | E7: -25612.55 | F7: -28826.23 | G7: 305703.49 | H7: 245000.87 | I7: 70973.67 | J7: 123431.16 | K7: 145457.43 | L7: 39013.73 | M7: 60702.62 | N7: 5758.6 | O7: 229097.71 | P7: 18890.75 | Q7: 35303.52 | R7: -16412.77
A8: Tata Motors | B8: 2022 | C8: 281617.5 | D8: 27144.14 | E8: 2308.45 | F8: -11441.47 | G8: 329061.49 | H8: 280229.19 | I8: 103721.61 | J8: 146977.54 | K8: 150682.81 | L8: 35240.34 | M8: 48832.3 | N8: 9311.86 | O8: 212282.14 | P8: 14282.83 | Q8: 15168.42 | R8: -885.59
A9: Tata Motors | B9: 2023 | C9: 352871.35 | D9: 38479.77 | E9: 13619.41 | F9: 2414.29 | G9: 334674.43 | H9: 282074.92 | I9: 96264.3 | J9: 150700.69 | K9: 155027.33 | L9: 40755.39 | M9: 52599.51 | N9: 10225.48 | O9: 267419.29 | P9: 35388.01 | Q9: 19230.17 | R9: 16157.84
A10: Tata Motors | B10: 2024 | C10: 440393 | D10: 62616 | E10: 35377 | F10: 31399 | G10: 369521 | H10: 276427 | I10: 69819 | J10: 168392 | K10: 173616 | L10: 47788 | M10: 93094 | N10: 7594 | O10: 318500 | P10: 67915 | Q10: 31414 | R10: 36501
A11: Tata Motors | B11: 2025 | C11: 452193 | D11: 66990 | E11: 43734 | F11: 27830 | G11: 376973 | H11: 254219 | I11: 47859 | J11: 160325 | K11: 166684 | L11: 47269 | M11: 122754 | N11: 5083 | O11: 319160 | P11: 63102 | Q11: 38042 | R11: 25060
A12: Mahindra & Mahindra | B12: 2019 | C12: 107742.09 | D12: 17882.96 | E12: 13892.19 | F12: 5315.46 | G12: 161888.66 | H12: 113544.68 | I12: 43526.17 | J12: 69406.04 | K12: 58609.33 | L12: 12200.16 | M12: 48343.98 | N12: 5021.35 | O12: 73940.38 | P12: -4347.29 | Q12: 7340.01 | R12: -11687.3
A13: Mahindra & Mahindra | B13: 2022 | C13: 93545.23 | D13: 17887.32 | E13: 14379.82 | F13: 6577.32 | G13: 172388.49 | H13: 115563.23 | I13: 51057.61 | J13: 75148 | K13: 56288.33 | L13: 11595.82 | M13: 56825.26 | N13: 5018.05 | O13: 61592.86 | P13: 9247.55 | Q13: 6039.8 | R13: 3207.75
... A51: Apollo Tyres | B51: 2025 | C51: 26222.57 | D51: 3515.48 | E51: 2017.11 | F51: 1121.33 | G51: 27226.7 | H51: 12461 | I51: 2616.83 | J51: 9815.34 | K51: 7360.3 | L51: 5131.16 | M51: 14765.7 | N51: 470.45 | O51: 19285.7 | P51: 1823.14 | Q51: 768.61 | R51: 1054.53

Sheet Ratios
A1: Company/Ratios | B1: Year | C1: Net Profit Margin | D1: ROE | E1: ROA | F1: Debt to Equity | G1: Interest Coverage | H1: Debt to Asset | I1: Current Ratio | J1: Quick Ratio | K1: Asset Turnover | L1: Inventory Turnover | M1: CF to Debt | N1: Revenue CAGR
A2: Maruti Suzuki | B2: 2019 | C2: 0.08615229 | D2: 0.16236784 | E2: 0.11957567 | F2: 0.00016981641 | G2: 180.77075 | H2: 0.00012506116 | I2: 0.8737474 | J2: 0.63910879 | K2: 1.3879569 | L2: 19.110004 | M2: 825.1125
A3: Maruti Suzuki | B3: 2022 | C3: 0.042992628 | D3: 0.070111235 | E3: 0.83331543 | F3: 0.00059457652 | G3: 60.132701 | H3: 0.0070669101 | I3: 0.98648339 | J3: 0.77898787 | K3: 19.382752 | L3: 20.04909 | M3: 55.942249
A4: Maruti Suzuki | B4: 2023 | C4: 0.068488123 | D4: 0.13288278 | E4: 0.097060294 | F4: 0.00040296935 | G4: 71.314439 | H4: 0.00029433703 | I4: 0.57768074 | J4: 0.36464866 | K4: 1.4171843 | L4: 23.562348 | M4: 371.54217
A5: Maruti Suzuki | B5: 2024 | C5: 0.09225489 | D5: 0.15750619 | E5: 0.11697936 | F5: 0.00079055537 | G5: 118.15031 | H5: 0.00058714304 | I5: 0.8721476 | J5: 0.66722539 | K5: 1.2680017 | L5: 22.382624 | M5: 248.16987
A6: Maruti Suzuki | B6: 2025 | C6: 0.091669506 | D6: 0.15066724 | E6: 0.10987397 | F6: 0.00060889506 | G6: 130.90834 | H6: 0.00044403627 | I6: 0.96577419 | J6: 0.73963462 | K6: 1.198588 | L6: 19.098035 | M6: 275.36177
A7: Average + Trend | C7: =(0.7*(C6)+0.3*AVERAGE(C2:C6)) -> 0.087062101 | D7: =(0.7*(D6)+0.3*AVERAGE(D2:D6)) -> 0.14587918 | E7: =(0.7*(E6)+0.3*AVERAGE(E2:E6)) -> 0.15352006 | F7: =(0.7*(F6)+0.3*AVERAGE(F2:F6)) -> 0.00058023531 | G7: =(0.7*(G6)+0.3*AVERAGE(G2:G6)) -> 125.31243 | H7: =(0.7*(H6)+0.3*AVERAGE(H2:H6)) -> 0.00082187465 | I7: =(0.7*(I6)+0.3*AVERAGE(I2:I6)) -> 0.93259194 | J7: =(0.7*(J6)+0.3*AVERAGE(J2:J6)) -> 0.70912055 | ... M7: =(0.7*(M6)+0.3*AVERAGE(M2:M6)) -> 299.32096 | N7: 0.20574586
A8: Tata Motors | B8: 2019 | C8: -0.09442533 | D8: -0.47487621 | E8: -0.094294736 | F8: 1.1692027 | G8: -0.35111312 | H8: 0.23216506 | I8: 0.8485724 | J8: 0.58035832 | K8: 0.99861696 | L8: 5.8722329 | M8: 0.26616561
A9: Tata Motors | B9: 2022 | C9: -0.040627695 | D9: -0.23430127 | E9: -0.034770006 | F9: 2.124037 | G9: 2.9150073 | H9: 0.31520434 | I9: 0.97541013 | J9: 0.74153913 | K9: 0.85582029 | L9: 6.0238392 | M9: 0.13770351
A10: Tata Motors | B10: 2023 | C10: 0.0068418419 | D10: 0.045899477 | E10: 0.0072138466 | F10: 1.8301368 | G10: 3.763126 | H10: 0.28763566 | I10: 0.97209111 | J10: 0.70919947 | K10: 1.054372 | L10: 7.0377451 | M10: 0.36761302
A11: Tata Motors | B11: 2024 | C11: 0.071297682 | D11: 0.33728275 | E11: 0.084972167 | F11: 0.74998389 | G11: 8.2454569 | H11: 0.18894461 | I11: 0.96991061 | J11: 0.69465948 | K11: 1.1917942 | L11: 7.1942129 | M11: 0.97272949
A12: Tata Motors | B12: 2025 | C12: 0.061544517 | D12: 0.22671359 | E12: 0.073824916 | F12: 0.38987732 | G12: 13.179225 | H12: 0.12695604 | I12: 0.96184997 | J12: 0.67826546 | K12: 1.1995368 | L12: 6.7151288 | M12: 1.3184981
A13: Average + Trend | C13: =(0.7*(C12)+0.3*AVERAGE(C8:C12)) -> 0.043359023 | D13: =(0.7*(D12)+0.3*AVERAGE(D8:D12)) -> 0.15274261 | E13: =(0.7*(E12)+0.3*AVERAGE(E8:E12)) -> 0.053894212 | F13: =(0.7*(F12)+0.3*AVERAGE(F8:F12)) -> 0.64870838 | G13: =(0.7*(G12)+0.3*AVERAGE(G8:G12)) -> 10.89056 | H13: =(0.7*(H12)+0.3*AVERAGE(H8:H12)) -> 0.15792357 | I13: =(0.7*(I12)+0.3*AVERAGE(I8:I12)) -> 0.95696503 | J13: =(0.7*(J12)+0.3*AVERAGE(J8:J12)) -> 0.67902713 | ... M13: =(0.7*(M12)+0.3*AVERAGE(M8:M12)) -> 1.1067112 | N13: 0.17099417
A14: Mahindra & Mahindra | B14: 2019 | C14: 0.049335037 | D14: 0.10995081 | E14: 0.032834048 | F14: 0.90034312 | G14: 3.5613849 | H14: 0.26886485 | I14: 1.1842149 | J14: 0.97605415 | K14: 0.66553204 | L14: 6.0606074 | M14: -0.099877614
A15: Mahindra & Mahindra | B15: 2022 | C15: 0.070311656 | D15: 0.11574641 | E15: 0.038154055 | F15: 0.898502 | G15: 3.5645958 | H15: 0.2961776 | I15: 1.3350547 | J15: 1.1290472 | K15: 0.54264197 | L15: 5.3116433 | M15: 0.18111992
A16: Mahindra & Mahindra | B16: 2023 | C16: 0.080974603 | D16: 0.15326739 | E16: 0.050329658 | F16: 0.86326876 | G16: 4.1591746 | H16: 0.28347857 | I16: 1.2939388 | J16: 1.0551302 | K16: 0.62154868 | L16: 6.0826641 | M16: -0.12215565
A17: Mahindra & Mahindra | B17: 2024 | C17: 0.079146981 | D17: 0.14168853 | E17: 0.048008506 | F17: 0.88686862 | G17: 3.7645552 | H17: 0.30049884 | I17: 1.3007452 | J17: 1.0546626 | K17: 0.60657407 | L17: 5.442005 | M17: -0.079819394
A18: Mahindra & Mahindra | B18: 2025 | C18: 0.079354056 | D18: 0.13876405 | E18: 0.046842332 | F18: 0.88949685 | G18: 3.7691501 | H18: 0.30026586 | I18: 1.4013558 | J18: 1.1762619 | K18: 0.59029537 | L18: 5.5349201 | M18: 0.038319405
A19: Average + Trend | C19: =(0.7*(C18)+0.3*AVERAGE(C14:C18)) -> 0.077095179 | D19: =(0.7*(D18)+0.3*AVERAGE(D14:D18)) -> 0.13669986 | E19: =(0.7*(E18)+0.3*AVERAGE(E14:E18)) -> 0.045759748 | F19: =(0.7*(F18)+0.3*AVERAGE(F14:F18)) -> 0.88895655 | G19: =(0.7*(G18)+0.3*AVERAGE(G14:G18)) -> 3.7675367 | H19: =(0.7*(H18)+0.3*AVERAGE(H14:H18)) -> 0.29714325 | I19: =(0.7*(I18)+0.3*AVERAGE(I14:I18)) -> 1.3718676 | J19: =(0.7*(J18)+0.3*AVERAGE(J14:J18)) -> 1.1468527 | ... M19: =(0.7*(M18)+0.3*AVERAGE(M14:M18)) -> 0.021878784 | N19: 0.14781331
A20: Ashok Leyland | B20: 2019 | C20: 0.061507698 | D20: 0.21166645 | E20: 0.053128898 | F20: 1.3247253 | G20: 3.3612871 | H20: 0.33250992 | I20: 1.0764274 | J20: 0.87568045 | K20: 0.8637764 | L20: 8.2782331 | M20: -0.2879009
A21: Ashok Leyland | B21: 2022 | C21: -0.013410222 | D21: -0.041746603 | E21: -0.0082299738 | F21: 1.7994857 | G21: 1.3565287 | H21: 0.3547527 | I21: 1.0012033 | J21: 0.86473122 | K21: 0.61370897 | L21: 8.0262542 | M21: 0.18402018
A22: Ashok Leyland | B22: 2023 | C22: 0.029146577 | D22: 0.11473989 | E22: 0.022646792 | F22: 1.8240252 | G22: 2.511894 | H22: 0.3600171 | I22: 1.0796479 | J22: 0.92643315 | K22: 0.77699662 | L22: 11.041746 | M22: -0.22848359
A23: Ashok Leyland | B23: 2024 | C23: 0.053104453 | D23: 0.21020789 | E23: 0.036741119 | F23: 2.2723531 | G23: 2.6877727 | H23: 0.39717252 | I23: 1.0917023 | J23: 0.94147661 | K23: 0.69186514 | L23: 9.0799013 | M23: -0.23309862
A24: Ashok Leyland | B24: 2025 | C24: 0.062165578 | D24: 0.1960762 | E24: 0.038098597 | F24: 2.307898 | G24: 2.4459736 | H24: 0.44843623 | I24: 1.2895803 | J24: 1.1394537 | K24: 0.61285679 | L24: 8.500147 | M24: 0.0035131502
A25: Average + Trend | C25: =(0.7*(C24)+0.3*AVERAGE(C20:C24)) -> 0.05506675 | D25: =(0.7*(D24)+0.3*AVERAGE(D20:D24)) -> 0.17870997 | E25: =(0.7*(E24)+0.3*AVERAGE(E20:E24)) -> 0.035212144 | F25: =(0.7*(F24)+0.3*AVERAGE(F20:F24)) -> 2.1872378 | G25: =(0.7*(G24)+0.3*AVERAGE(G20:G24)) -> 2.4539889 | H25: =(0.7*(H24)+0.3*AVERAGE(H20:H24)) -> 0.42747867 | I25: =(0.7*(I24)+0.3*AVERAGE(I20:I24)) -> 1.2350199 | J25: =(0.7*(J24)+0.3*AVERAGE(J20:J24)) -> 1.0824841 | ... M25: =(0.7*(M24)+0.3*AVERAGE(M20:M24)) -> -0.031257782 | N25: 0.13928835
A26: Eicher Motors | B26: 2019 | C26: 0.20980679 | D26: 0.24697827 | E26: 0.19344541 | F26: 0 | G26: 491.80082 | H26: 0 | I26: 2.104573 | J26: 1.8026702 | K26: 0.92201693 | L26: 9.5346238 | M26: 0
A27: Eicher Motors | B27: 2022 | C27: 0.15525799 | D27: 0.13297906 | E27: 0.10387966 | F27: 0.0028013959 | G27: 142.34398 | H27: 0.002188375 | I27: 1.9421436 | J27: 1.5507661 | K27: 0.66907768 | L27: 6.1675026 | M27: 43.234428
A28: Eicher Motors | B28: 2023 | C28: 0.18980281 | D28: 0.19438863 | E28: 0.15178637 | F28: 0.0087223187 | G28: 155.38401 | H28: 0.006810733 | I28: 1.1387043 | J28: 0.74346283 | K28: 0.79970559 | L28: 6.9610577 | M28: 21.588222
A29: Eicher Motors | B29: 2024 | C29: 0.2215476 | D29: 0.22171751 | E29: 0.17309053 | F29: 0.015041952 | G29: 114.98624 | H29: 0.011742958 | I29: 1.1536568 | J29: 0.76191707 | K29: 0.78127919 | L29: 7.0651008 | M29: 13.718354
A30: Eicher Motors | B30: 2025 | C30: 0.22679887 | D30: 0.22231081 | E30: 0.17422421 | F30: 0.01447046 | G30: 123.60582 | H30: 0.011340449 | I30: 1.63022 | J30: 1.2636399 | K30: 0.76818816 | L30: 9.4650452 | M30: 12.91469
A31: Average + Trend | C31: =(0.7*(C30)+0.3*AVERAGE(C26:C30)) -> 0.21895205 | D31: =(0.7*(D30)+0.3*AVERAGE(D26:D30)) -> 0.21672003 | E31: =(0.7*(E30)+0.3*AVERAGE(E26:E30)) -> 0.16974251 | F31: =(0.7*(F30)+0.3*AVERAGE(F26:F30)) -> 0.012591489 | G31: =(0.7*(G30)+0.3*AVERAGE(G26:G30)) -> 148.21132 | H31: =(0.7*(H30)+0.3*AVERAGE(H26:H30)) -> 0.0098632649 | I31: =(0.7*(I30)+0.3*AVERAGE(I26:I30)) -> 1.6193119 | J31: =(0.7*(J30)+0.3*AVERAGE(J26:J30)) -> 1.2518953 | ... M31: =(0.7*(M30)+0.3*AVERAGE(M26:M30)) -> 14.527625 | N31: 0.25746334
A32: Bajaj Auto | B32: 2019 | C32: 0.15211551 | D32: 0.21208781 | E32: 0.17089339 | F32: 0.0053594286 | G32: 1612.8906 | H32: 0.0043184515 | I32: 1.4512678 | J32: 1.2539856 | K32: 1.1234449 | L32: 24.155755 | M32: 19.971571
A33: Bajaj Auto | B33: 2022 | C33: 0.17211134 | D33: 0.20649498 | E33: 0.17560973 | F33: 0.0041115672 | G33: 915.71594 | H33: 0.0034966041 | I33: 2.2108585 | J33: 1.9484057 | K33: 1.0203263 | L33: 20.81467 | M33: 34.187587
A34: Bajaj Auto | B34: 2023 | C34: 0.15875982 | D34: 0.20639953 | E34: 0.17247645 | F34: 0.0042310437 | G34: 206.71577 | H34: 0.0035356446 | I34: 1.8309365 | J34: 1.5342893 | K34: 1.0863986 | L34: 19.919866 | M34: 42.481043
A35: Bajaj Auto | B35: 2024 | C35: 0.16550508 | D35: 0.26614627 | E35: 0.19592062 | F35: 0.026212243 | G35: 173.37922 | H35: 0.019295852 | I35: 1.2977749 | J35: 1.1120189 | K35: 1.1837741 | L35: 20.751167 | M35: 8.6385921
A36: Bajaj Auto | B36: 2025 | C36: 0.1396012 | D36: 0.20815545 | E36: 0.1353676 | F36: 0.17648766 | G36: 28.353458 | H36: 0.11477341 | I36: 1.6787162 | J36: 1.4993832 | K36: 0.96967358 | L36: 19.826038 | M36: -0.22632593
A37: Average + Trend | C37: =(0.7*(C36)+0.3*AVERAGE(C32:C36)) -> 0.14500642 | D37: =(0.7*(D36)+0.3*AVERAGE(D32:D36)) -> 0.21166586 | E37: =(0.7*(E36)+0.3*AVERAGE(E32:E36)) -> 0.14577339 | F37: =(0.7*(F36)+0.3*AVERAGE(F32:F36)) -> 0.13652548 | G37: =(0.7*(G36)+0.3*AVERAGE(G32:G36)) -> 196.07072 | H37: =(0.7*(H36)+0.3*AVERAGE(H32:H36)) -> 0.089066584 | I37: =(0.7*(I36)+0.3*AVERAGE(I32:I36)) -> 1.6832746 | J37: =(0.7*(J36)+0.3*AVERAGE(J32:J36)) -> 1.4904532 | ... M37: =(0.7*(M36)+0.3*AVERAGE(M32:M36)) -> 6.1447199 | N37: 0.17439233
A38: Hero Motocorp | B38: 2019 | C38: 0.099200969 | D38: 0.26019603 | E38: 0.18612316 | F38: 0.009431482 | G38: 155.08123 | H38: 0.0067465181 | I38: 1.9081122 | J38: 1.6247193 | K38: 1.8762232 | L38: 22.106832 | M38: 8.2688241
A39: Hero Motocorp | B39: 2022 | C39: 0.076956676 | D39: 0.14485298 | E39: 0.10307144 | F39: 0.015735212 | G39: 71.576836 | H39: 0.011196531 | I39: 1.9160799 | J39: 1.6492244 | K39: 1.3393437 | L39: 15.618741 | M39: 8.35863
A40: Hero Motocorp | B40: 2023 | C40: 0.08090756 | D40: 0.16745259 | E40: 0.11748783 | F40: 0.014287902 | G40: 44.487891 | H40: 0.010024656 | I40: 1.5692543 | J40: 1.2771371 | K40: 1.4521243 | L40: 16.397628 | M40: 10.901902
...

Sheet Credit Scores
A1: Company/Ratios | B1: Net Profit Margin | C1: ROE | D1: ROA | E1: Debt to Equity | F1: Interest Coverage | G1: Debt to Asset | H1: Current Ratio | I1: Quick Ratio | J1: Asset Turnover | K1: Inventory Turnover | L1: CF to Debt | M1: Revenue CAGR
A2: Maruti Suzuki | B2: 8.7062101 | C2: 14.587918 | D2: 15.352006 | E2: 0.00058023531 | F2: 125.31243 | G2: 0.00082187465 | H2: 0.93259194 | I2: 0.70912055 | J2: 2.3182806 | K2: 19.620751 | L2: 299.32096 | M2: 20.574586
A3: Tata Motors | B3: 4.3359023 | C3: 15.274261 | D3: 5.3894212 | E3: 0.64870838 | F3: 10.89056 | G3: 0.15792357 | H3: 0.95696503 | I3: 0.67902713 | J3: 1.1576842 | K3: 6.6711797 | L3: 1.1067112 | M3: 17.099417
A4: Mahindra & Mahindra | B4: 7.7095179 | C4: 13.669986 | D4: 4.5759748 | E4: 0.88895655 | F4: 3.7675367 | G4: 0.29714325 | H4: 1.3718676 | I4: 1.1468527 | J4: 0.59480229 | K4: 5.5803545 | L4: 0.021878784 | M4: 14.781331
A5: Ashok Leyland | B5: 5.506675 | C5: 17.870997 | D5: 3.5212144 | E5: 2.1872378 | F5: 2.4539889 | G5: 0.42747867 | H5: 1.2350199 | I5: 1.0824841 | J5: 0.64255199 | K5: 8.6456798 | L5: -0.031257782 | M5: 13.928835
A6: Eicher Motors | B6: 21.895205 | C6: 21.672003 | D6: 16.974251 | E6: 0.012591489 | F6: 148.21132 | G6: 0.0098632649 | H6: 1.6193119 | I6: 1.2518953 | J6: 0.77414776 | K6: 8.9771314 | L6: 14.527625 | M6: 25.746334
A7: Bajaj Auto | B7: 14.500642 | C7: 21.166586 | D7: 14.577339 | E7: 0.13652548 | F7: 196.07072 | G7: 0.089066584 | H7: 1.6832746 | I7: 1.4904532 | J7: 1.0017886 | K7: 20.206276 | L7: 6.1447199 | M7: 17.439233
A8: Hero Motocorp | B8: 10.052938 | C8: 21.844058 | D8: 15.020292 | E8: 0.010722157 | F8: 94.382022 | G8: 0.0073873889 | H8: 1.7770928 | I8: 1.5069296 | J8: 1.4921739 | K8: 16.290812 | L8: 19.78065 | M8: 6.5249913
A9: TVS Motors | B9: 5.5946553 | C9: 22.826253 | D9: 4.4558701 | E9: 1.5623597 | F9: 3.1536063 | G9: 0.30427536 | H9: 1.0832152 | I9: 0.97500774 | J9: 0.89815785 | K9: 12.97039 | L9: 0.12464081 | M9: 29.840893
A10: MRF | B10: 6.2783911 | C10: 9.6573073 | D10: 6.0012463 | E10: 0.067662776 | F10: 11.689993 | G10: 0.04187246 | H10: 1.4738839 | I10: 0.86035226 | J10: 0.95309221 | K10: 4.2541144 | L10: 1.5658876 | M10: 20.107484
A11: Apollo Tyres | B11: 4.3219669 | C11: 7.7458957 | D11: 4.0886067 | E11: 0.22098974 | F11: 7.4904007 | G11: 0.11390034 | H11: 1.2990159 | I11: 0.62127721 | J11: 0.94251839 | K11: 4.0898744 | L11: 0.66055581 | M11: 14.058904
A15: SCORES
A16: Company/Ratios | B16: Net Profit Margin | C16: ROE | D16: ROA | E16: Debt to Equity | F16: Interest Coverage | G16: Debt to Asset | H16: Current Ratio | I16: Quick Ratio | J16: Asset Turnover | K16: Inventory Turnover | L16: Revenue CAGR | M16: CF to Debt
A17: Maruti Suzuki | B17: 2 | C17: 3 | D17: 4 | E17: 5 | F17: 5 | G17: 5 | H17: 2 | I17: 2 | J17: 5 | K17: 4 | L17: 5 | M17: 5
A18: Tata Motors | B18: 1 | C18: 4 | D18: 2 | E18: 3 | F18: 4 | G18: 4 | H18: 2 | I18: 2 | J18: 3 | K18: 2 | L18: 4 | M18: 3
A19: Mahindra & Mahindra | B19: 2 | C19: 3 | D19: 1 | E19: 2 | F19: 1 | G19: 3 | H19: 4 | I19: 4 | J19: 1 | K19: 2 | L19: 3 | M19: 0
A20: Ashok Leyland | B20: 2 | C20: 4 | D20: 1 | E20: 1 | F20: 1 | G20: 3 | H20: 4 | I20: 4 | J20: 1 | K20: 2 | L20: 3 | M20: 0
A21: Eicher Motors | B21: 5 | C21: 5 | D21: 4 | E21: 5 | F21: 5 | G21: 5 | H21: 5 | I21: 5 | J21: 1 | K21: 2 | L21: 3 | M21: 5
A22: Bajaj Auto | B22: 3 | C22: 5 | D22: 3 | E22: 5 | F22: 5 | G22: 5 | H22: 5 | I22: 5 | J22: 2 | K22: 5 | L22: 3 | M22: 5
A23: Hero Motocorp | B23: 3 | C23: 5 | D23: 4 | E23: 5 | F23: 5 | G23: 5 | H23: 5 | I23: 5 | J23: 3 | K23: 4 | L23: 2 | M23: 5
A24: TVS Motors | B24: 2 | C24: 5 | D24: 1 | E24: 1 | F24: 1 | G24: 3 | H24: 3 | I24: 3 | J24: 1 | K24: 3 | L24: 5 | M24: 1
A25: MRF | B25: 2 | C25: 2 | D25: 2 | E25: 5 | F25: 3 | G25: 5 | H25: 5 | I25: 3 | J25: 2 | K25: 1 | L25: 5 | M25: 3
A26: Apollo Tyres | B26: 1 | C26: 2 | D26: 1 | E26: 4 | F26: 2 | G26: 4 | H26: 4 | I26: 2 | J26: 2 | K26: 1 | L26: 3 | M26: 2
C29: Company/Ratios | D29: Profitability Ratio | E29: Leverage Score | F29: Liquidity Score | G29: Efficiency Score | H29: Credit Score
C30: Maruti Suzuki | D30: 3 | E30: 5 | F30: 2 | G30: 4.6666667 | H30: =0.3*D30 + 0.4*E30 + 0.15*F30 + 0.15*G30 -> 3.9
C31: Tata Motors | D31: 2.3333333 | E31: 3.6666667 | F31: 2 | G31: 3 | H31: =0.3*D31 + 0.4*E31 + 0.15*F31 + 0.15*G31 -> 2.9166667
C32: Mahindra & Mahindra | D32: 2 | E32: 2 | F32: 4 | G32: 2 | H32: =0.3*D32 + 0.4*E32 + 0.15*F32 + 0.15*G32 -> 2.3
C33: Ashok Leyland | D33: 2.3333333 | E33: 1.6666667 | F33: 4 | G33: 2 | H33: =0.3*D33 + 0.4*E33 + 0.15*F33 + 0.15*G33 -> 2.2666667
C34: Eicher Motors | D34: 4.6666667 | E34: 5 | F34: 5 | G34: 2 | H34: =0.3*D34 + 0.4*E34 + 0.15*F34 + 0.15*G34 -> 4.45
C35: Bajaj Auto | D35: 3.6666667 | E35: 5 | F35: 5 | G35: 3.3333333 | H35: =0.3*D35 + 0.4*E35 + 0.15*F35 + 0.15*G35 -> 4.35
C36: Hero Motocorp | D36: 4 | E36: 5 | F36: 5 | G36: 3 | H36: =0.3*D36 + 0.4*E36 + 0.15*F36 + 0.15*G36 -> 4.4
C37: TVS Motors | D37: 2.6666667 | E37: 1.6666667 | F37: 3 | G37: 3 | H37: =0.3*D37 + 0.4*E37 + 0.15*F37 + 0.15*G37 -> 2.3666667
C38: MRF | D38: 2 | E38: 4.3333333 | F38: 4 | G38: 2.6666667 | H38: =0.3*D38 + 0.4*E38 + 0.15*F38 + 0.15*G38 -> 3.3333333
C39: Apollo Tyres | D39: 1.3333333 | E39: 3.3333333 | F39: 3 | G39: 2 | H39: =0.3*D39 + 0.4*E39 + 0.15*F39 + 0.15*G39 -> 2.4833333

Sheet Credit Ratings
B3: WEIGHTS | C3: 0.3 | D3: 0.4 | E3: 0.15 | F3: 0.15 | G3: 1
B4: Company | C4: Profitability Ratio | D4: Leverage Score | E4: Liquidity Score | F4: Efficiency Score | G4: Credit Score | H4: Credit Ratings
B5: Maruti Suzuki | C5: 3 | D5: 5 | E5: 2 | F5: 4.6666667 | G5: =0.3*C5+0.4*D5+0.15*E5+0.15*F5 -> 3.9 | H5: A
B6: Tata Motors | C6: 2.3333333 | D6: 3.6666667 | E6: 2 | F6: 3 | G6: =0.3*C6+0.4*D6+0.15*E6+0.15*F6 -> 2.9166667 | H6: B | K6: Interval | L6: Rating
B7: Mahindra & Mahindra | C7: 2 | D7: 2 | E7: 4 | F7: 2 | G7: =0.3*C7+0.4*D7+0.15*E7+0.15*F7 -> 2.3 | H7: C+ | K7: >4.00 | L7: A+
B8: Ashok Leyland | C8: 2.3333333 | D8: 1.6666667 | E8: 4 | F8: 2 | G8: =0.3*C8+0.4*D8+0.15*E8+0.15*F8 -> 2.2666667 | H8: C+ | K8: 3.5 - 4.00 | L8: A
B9: Eicher Motors | C9: 4.6666667 | D9: 5 | E9: 5 | F9: 2 | G9: =0.3*C9+0.4*D9+0.15*E9+0.15*F9 -> 4.45 | H9: A+ | K9: 3.0 - 3.49 | L9: B+
B10: Bajaj Auto | C10: 3.6666667 | D10: 5 | E10: 5 | F10: 3.3333333 | G10: =0.3*C10+0.4*D10+0.15*E10+0.15*F10 -> 4.35 | H10: A+ | K10: 2.5 - 2.99 | L10: B
B11: Hero Motocorp | C11: 4 | D11: 5 | E11: 5 | F11: 3 | G11: =0.3*C11+0.4*D11+0.15*E11+0.15*F11 -> 4.4 | H11: A+ | K11: 2.0 - 2.49 | L11: C+
B12: TVS Motors | C12: 2.6666667 | D12: 1.6666667 | E12: 3 | F12: 3 | G12: =0.3*C12+0.4*D12+0.15*E12+0.15*F12 -> 2.3666667 | H12: C+ | K12: 1.5 - 1.99 | L12: C
B13: MRF | C13: 2 | D13: 4.3333333 | E13: 4 | F13: 2.6666667 | G13: =0.3*C13+0.4*D13+0.15*E13+0.15*F13 -> 3.3333333 | H13: B+
B14: Apollo Tyres | C14: 1.3333333 | D14: 3.3333333 | E14: 3 | F14: 2 | G14: =0.3*C14+0.4*D14+0.15*E14+0.15*F14 -> 2.4833333 | H14: C+

Sheet Expected Loss
D3: Expected Loss (EL) = Probability of Default(PD) * Loss Given a Default * Exposure
D5: Company | E5: PD | F5: LGD | G5: EXPOSURE | H5: EL9(Percentage)
A6: Based on Values of Credit Rating Companies | D6: Maruti Suzuki | E6: 0.002 | F6: 0.4 | G6: 100 | H6: =(E6*F6*G6) -> 0.08
A7: Credit Ratings | B7: PD | D7: Tata Motors | E7: 0.012 | F7: 0.4 | G7: 100 | H7: =(E7*F7*G7) -> 0.48
A8: A+ | B8: 0.001 | D8: Mahindra & Mahindra | E8: 0.04 | F8: 0.4 | G8: 100 | H8: =(E8*F8*G8) -> 1.6
A9: A | B9: 0.002 | D9: Ashok Leyland | E9: 0.04 | F9: 0.4 | G9: 100 | H9: =(E9*F9*G9) -> 1.6 | J9: Exposure | K9: 100 | L9: (Constant) Assumption
A10: B+ | B10: 0.006 | D10: Eicher Motors | E10: 0.001 | F10: 0.4 | G10: 100 | H10: =(E10*F10*G10) -> 0.04 | J10: LGD | K10: 0.4 | L10: Industry Average
A11: B | B11: 0.012 | D11: Bajaj Auto | E11: 0.001 | F11: 0.4 | G11: 100 | H11: =(E11*F11*G11) -> 0.04
A12: C+ | B12: 0.04 | D12: Hero Motocorp | E12: 0.001 | F12: 0.4 | G12: 100 | H12: =(E12*F12*G12) -> 0.04
A13: C | B13: 0.1 | D13: TVS Motors | E13: 0.04 | F13: 0.4 | G13: 100 | H13: =(E13*F13*G13) -> 1.6
D14: MRF | E14: 0.006 | F14: 0.4 | G14: 100 | H14: =(E14*F14*G14) -> 0.24
D15: Apollo Tyres | E15: 0.04 | F15: 0.4 | G15: 100 | H15: =(E15*F15*G15) -> 1.6

Sheet Scenario Ananlysis
D2: Scenario 1 | E2: Scenario 2 | G2: Interval | H2: Rating
C3: Ratios | D3: Mild Stress | E3: Severe Stress | G3: >4.00 | H3: A+
C4: Profitability | D4: -0.1 | E4: -0.2 | G4: 3.5 - 4.00 | H4: A
C5: Leverage | D5: -0.05 | E5: -0.1 | G5: 3.0 - 3.49 | H5: B+
C6: Liquidity | D6: -0.08 | E6: -0.18 | G6: 2.5 - 2.99 | H6: B
C7: Efficiency | D7: -0.05 | E7: -0.12 | G7: 2.0 - 2.49 | H7: C+
G8: 1.5 - 1.99 | H8: C
C11: Scenario 1 Mild Stress
C12: Company/Ratios | D12: Profitability Ratio | E12: Leverage Score | F12: Liquidity Score | G12: Efficiency Score | H12: Credit Score | I12: Credit Rating
C13: Maruti Suzuki | D13: ='Credit Scores'!D30*(100% +('Scenario Ananlysis'!$D$4)) -> 2.7 | E13: ='Credit Scores'!E30*(100%+('Scenario Ananlysis'!$D$5)) -> 4.75 | F13: ='Credit Scores'!F30*(100%+('Scenario Ananlysis'!$D$6)) -> 1.84 | G13: ='Credit Scores'!G30*(100% + ('Scenario Ananlysis'!$D$7)) -> 4.4333333 | H13: =0.3*D13+0.4*E13+0.15*F13+0.15*G13 -> 3.651 | I13: B+
C14: Tata Motors | D14: ='Credit Scores'!D31*(100% +('Scenario Ananlysis'!$D$4)) -> 2.1 | E14: ='Credit Scores'!E31*(100%+('Scenario Ananlysis'!$D$5)) -> 3.4833333 | F14: ='Credit Scores'!F31*(100%+('Scenario Ananlysis'!$D$6)) -> 1.84 | G14: ='Credit Scores'!G31*(100% + ('Scenario Ananlysis'!$D$7)) -> 2.85 | H14: =0.3*D14+0.4*E14+0.15*F14+0.15*G14 -> 2.7268333 | I14: C+
C15: Mahindra & Mahindra | D15: ='Credit Scores'!D32*(100% +('Scenario Ananlysis'!$D$4)) -> 1.8 | E15: ='Credit Scores'!E32*(100%+('Scenario Ananlysis'!$D$5)) -> 1.9 | F15: ='Credit Scores'!F32*(100%+('Scenario Ananlysis'!$D$6)) -> 3.68 | G15: ='Credit Scores'!G32*(100% + ('Scenario Ananlysis'!$D$7)) -> 1.9 | H15: =0.3*D15+0.4*E15+0.15*F15+0.15*G15 -> 2.137 | I15: C
C16: Ashok Leyland | D16: ='Credit Scores'!D33*(100% +('Scenario Ananlysis'!$D$4)) -> 2.1 | E16: ='Credit Scores'!E33*(100%+('Scenario Ananlysis'!$D$5)) -> 1.5833333 | F16: ='Credit Scores'!F33*(100%+('Scenario Ananlysis'!$D$6)) -> 3.68 | G16: ='Credit Scores'!G33*(100% + ('Scenario Ananlysis'!$D$7)) -> 1.9 | H16: =0.3*D16+0.4*E16+0.15*F16+0.15*G16 -> 2.1003333 | I16: C
C17: Eicher Motors | D17: ='Credit Scores'!D34*(100% +('Scenario Ananlysis'!$D$4)) -> 4.2 | E17: ='Credit Scores'!E34*(100%+('Scenario Ananlysis'!$D$5)) -> 4.75 | F17: ='Credit Scores'!F34*(100%+('Scenario Ananlysis'!$D$6)) -> 4.6 | G17: ='Credit Scores'!G34*(100% + ('Scenario Ananlysis'!$D$7)) -> 1.9 | H17: =0.3*D17+0.4*E17+0.15*F17+0.15*G17 -> 4.135 | I17: A+
C18: Bajaj Auto | D18: ='Credit Scores'!D35*(100% +('Scenario Ananlysis'!$D$4)) -> 3.3 | E18: ='Credit Scores'!E35*(100%+('Scenario Ananlysis'!$D$5)) -> 4.75 | F18: ='Credit Scores'!F35*(100%+('Scenario Ananlysis'!$D$6)) -> 4.6 | G18: ='Credit Scores'!G35*(100% + ('Scenario Ananlysis'!$D$7)) -> 3.1666667 | H18: =0.3*D18+0.4*E18+0.15*F18+0.15*G18 -> 4.055 | I18: A+
C19: Hero Motocorp | D19: ='Credit Scores'!D36*(100% +('Scenario Ananlysis'!$D$4)) -> 3.6 | E19: ='Credit Scores'!E36*(100%+('Scenario Ananlysis'!$D$5)) -> 4.75 | F19: ='Credit Scores'!F36*(100%+('Scenario Ananlysis'!$D$6)) -> 4.6 | G19: ='Credit Scores'!G36*(100% + ('Scenario Ananlysis'!$D$7)) -> 2.85 | H19: =0.3*D19+0.4*E19+0.15*F19+0.15*G19 -> 4.0975 | I19: A+
C20: TVS Motors | D20: ='Credit Scores'!D37*(100% +('Scenario Ananlysis'!$D$4)) -> 2.4 | E20: ='Credit Scores'!E37*(100%+('Scenario Ananlysis'!$D$5)) -> 1.5833333 | F20: ='Credit Scores'!F37*(100%+('Scenario Ananlysis'!$D$6)) -> 2.76 | G20: ='Credit Scores'!G37*(100% + ('Scenario Ananlysis'!$D$7)) -> 2.85 | H20: =0.3*D20+0.4*E20+0.15*F20+0.15*G20 -> 2.1948333 | I20: C+
C21: MRF | D21: ='Credit Scores'!D38*(100% +('Scenario Ananlysis'!$D$4)) -> 1.8 | E21: ='Credit Scores'!E38*(100%+('Scenario Ananlysis'!$D$5)) -> 4.1166667 | F21: ='Credit Scores'!F38*(100%+('Scenario Ananlysis'!$D$6)) -> 3.68 | G21: ='Credit Scores'!G38*(100% + ('Scenario Ananlysis'!$D$7)) -> 2.5333333 | H21: =0.3*D21+0.4*E21+0.15*F21+0.15*G21 -> 3.1186667 | I21: B
C22: Apollo Tyres | D22: ='Credit Scores'!D39*(100% +('Scenario Ananlysis'!$D$4)) -> 1.2 | E22: ='Credit Scores'!E39*(100%+('Scenario Ananlysis'!$D$5)) -> 3.1666667 | F22: ='Credit Scores'!F39*(100%+('Scenario Ananlysis'!$D$6)) -> 2.76 | G22: ='Credit Scores'!G39*(100% + ('Scenario Ananlysis'!$D$7)) -> 1.9 | H22: =0.3*D22+0.4*E22+0.15*F22+0.15*G22 -> 2.3256667 | I22: C+
C25: Scenario 2 Severe Stress
C26: Company/Ratios | D26: Profitability Ratio | E26: Leverage Score | F26: Liquidity Score | G26: Efficiency Score | H26: Credit Score | I26: Credit Rating
C27: Maruti Suzuki | D27: ='Credit Scores'!D30*(100%+('Scenario Ananlysis'!$E$4)) -> 2.4 | E27: ='Credit Scores'!E30*(100% +('Scenario Ananlysis'!$E$5)) -> 4.5 | F27: ='Credit Scores'!F30*(100% +('Scenario Ananlysis'!$E$6)) -> 1.64 | G27: ='Credit Scores'!G30*(100% +('Scenario Ananlysis'!$E$7)) -> 4.1066667 | H27: =0.3*D27+0.4*E27+0.15*F27+0.15*G27 -> 3.382 | I27: B+
C28: Tata Motors | D28: ='Credit Scores'!D31*(100%+('Scenario Ananlysis'!$E$4)) -> 1.8666667 | E28: ='Credit Scores'!E31*(100% +('Scenario Ananlysis'!$E$5)) -> 3.3 | F28: ='Credit Scores'!F31*(100% +('Scenario Ananlysis'!$E$6)) -> 1.64 | G28: ='Credit Scores'!G31*(100% +('Scenario Ananlysis'!$E$7)) -> 2.64 | H28: =0.3*D28+0.4*E28+0.15*F28+0.15*G28 -> 2.522 | I28: B
C29: Mahindra & Mahindra | D29: ='Credit Scores'!D32*(100%+('Scenario Ananlysis'!$E$4)) -> 1.6 | E29: ='Credit Scores'!E32*(100% +('Scenario Ananlysis'!$E$5)) -> 1.8 | F29: ='Credit Scores'!F32*(100% +('Scenario Ananlysis'!$E$6)) -> 3.28 | G29: ='Credit Scores'!G32*(100% +('Scenario Ananlysis'!$E$7)) -> 1.76 | H29: =0.3*D29+0.4*E29+0.15*F29+0.15*G29 -> 1.956 | I29: C
C30: Ashok Leyland | D30: ='Credit Scores'!D33*(100%+('Scenario Ananlysis'!$E$4)) -> 1.8666667 | E30: ='Credit Scores'!E33*(100% +('Scenario Ananlysis'!$E$5)) -> 1.5 | F30: ='Credit Scores'!F33*(100% +('Scenario Ananlysis'!$E$6)) -> 3.28 | G30: ='Credit Scores'!G33*(100% +('Scenario Ananlysis'!$E$7)) -> 1.76 | H30: =0.3*D30+0.4*E30+0.15*F30+0.15*G30 -> 1.916 | I30: C
C31: Eicher Motors | D31: ='Credit Scores'!D34*(100%+('Scenario Ananlysis'!$E$4)) -> 3.7333333 | E31: ='Credit Scores'!E34*(100% +('Scenario Ananlysis'!$E$5)) -> 4.5 | F31: ='Credit Scores'!F34*(100% +('Scenario Ananlysis'!$E$6)) -> 4.1 | G31: ='Credit Scores'!G34*(100% +('Scenario Ananlysis'!$E$7)) -> 1.76 | H31: =0.3*D31+0.4*E31+0.15*F31+0.15*G31 -> 3.799 | I31: A
C32: Bajaj Auto | D32: ='Credit Scores'!D35*(100%+('Scenario Ananlysis'!$E$4)) -> 2.9333333 | E32: ='Credit Scores'!E35*(100% +('Scenario Ananlysis'!$E$5)) -> 4.5 | F32: ='Credit Scores'!F35*(100% +('Scenario Ananlysis'!$E$6)) -> 4.1 | G32: ='Credit Scores'!G35*(100% +('Scenario Ananlysis'!$E$7)) -> 2.9333333 | H32: =0.3*D32+0.4*E32+0.15*F32+0.15*G32 -> 3.735 | I32: A
C33: Hero Motocorp | D33: ='Credit Scores'!D36*(100%+('Scenario Ananlysis'!$E$4)) -> 3.2 | E33: ='Credit Scores'!E36*(100% +('Scenario Ananlysis'!$E$5)) -> 4.5 | F33: ='Credit Scores'!F36*(100% +('Scenario Ananlysis'!$E$6)) -> 4.1 | G33: ='Credit Scores'!G36*(100% +('Scenario Ananlysis'!$E$7)) -> 2.64 | H33: =0.3*D33+0.4*E33+0.15*F33+0.15*G33 -> 3.771 | I33: A
C34: TVS Motors | D34: ='Credit Scores'!D37*(100%+('Scenario Ananlysis'!$E$4)) -> 2.1333333 | E34: ='Credit Scores'!E37*(100% +('Scenario Ananlysis'!$E$5)) -> 1.5 | F34: ='Credit Scores'!F37*(100% +('Scenario Ananlysis'!$E$6)) -> 2.46 | G34: ='Credit Scores'!G37*(100% +('Scenario Ananlysis'!$E$7)) -> 2.64 | H34: =0.3*D34+0.4*E34+0.15*F34+0.15*G34 -> 2.005 | I34: C+
C35: MRF | D35: ='Credit Scores'!D38*(100%+('Scenario Ananlysis'!$E$4)) -> 1.6 | E35: ='Credit Scores'!E38*(100% +('Scenario Ananlysis'!$E$5)) -> 3.9 | F35: ='Credit Scores'!F38*(100% +('Scenario Ananlysis'!$E$6)) -> 3.28 | G35: ='Credit Scores'!G38*(100% +('Scenario Ananlysis'!$E$7)) -> 2.3466667 | H35: =0.3*D35+0.4*E35+0.15*F35+0.15*G35 -> 2.884 | I35: B
C36: Apollo Tyres | D36: ='Credit Scores'!D39*(100%+('Scenario Ananlysis'!$E$4)) -> 1.0666667 | E36: ='Credit Scores'!E39*(100% +('Scenario Ananlysis'!$E$5)) -> 3 | F36: ='Credit Scores'!F39*(100% +('Scenario Ananlysis'!$E$6)) -> 2.46 | G36: ='Credit Scores'!G39*(100% +('Scenario Ananlysis'!$E$7)) -> 1.76 | H36: =0.3*D36+0.4*E36+0.15*F36+0.15*G36 -> 2.153 | I36: C+

Sheet Rough Data
E1: 0.08615229 | F1: 0.16236784 | G1: ='Raw Financial Data'!F2/'Raw Financial Data'!G2 -> 0.11957567 | H1: ='Raw Financial Data'!I2/'Raw Financial Data'!M2 -> 0.00016981641 | I1: ='Raw Financial Data'!D2/'Raw Financial Data'!N2 -> 180.77075 | J1: ='Raw Financial Data'!I2/'Raw Financial Data'!G2 -> 0.00012506116 | K1: ='Raw Financial Data'!J2/'Raw Financial Data'!K2 -> 0.8737474 | L1: =('Raw Financial Data'!J2-'Raw Financial Data'!L2)/'Raw Financial Data'!K2 -> 0.63910879 | M1: ='Raw Financial Data'!C2/'Raw Financial Data'!G2 -> 1.3879569 | N1: 19.110004 | O1: ='Raw Financial Data'!P2/'Raw Financial Data'!I2 -> 825.1125
E2: 0.042992628 | F2: 0.070111235 | G2: ='Raw Financial Data'!F3/'Raw Financial Data'!G3 -> 0.83331543 | H2: ='Raw Financial Data'!I3/'Raw Financial Data'!M3 -> 0.00059457652 | I2: ='Raw Financial Data'!D3/'Raw Financial Data'!N3 -> 60.132701 | J2: ='Raw Financial Data'!I3/'Raw Financial Data'!G3 -> 0.0070669101 | K2: ='Raw Financial Data'!J3/'Raw Financial Data'!K3 -> 0.98648339 | L2: =('Raw Financial Data'!J3-'Raw Financial Data'!L3)/'Raw Financial Data'!K3 -> 0.77898787 | M2: ='Raw Financial Data'!C3/'Raw Financial Data'!G3 -> 19.382752 | N2: 20.04909 | O2: ='Raw Financial Data'!P3/'Raw Financial Data'!I3 -> 55.942249
E3: 0.068488123 | F3: 0.13288278 | G3: ='Raw Financial Data'!F4/'Raw Financial Data'!G4 -> 0.097060294 | H3: ='Raw Financial Data'!I4/'Raw Financial Data'!M4 -> 0.00040296935 | I3: ='Raw Financial Data'!D4/'Raw Financial Data'!N4 -> 71.314439 | J3: ='Raw Financial Data'!I4/'Raw Financial Data'!G4 -> 0.00029433703 | K3: ='Raw Financial Data'!J4/'Raw Financial Data'!K4 -> 0.57768074 | L3: =('Raw Financial Data'!J4-'Raw Financial Data'!L4)/'Raw Financial Data'!K4 -> 0.36464866 | M3: ='Raw Financial Data'!C4/'Raw Financial Data'!G4 -> 1.4171843 | N3: 23.562348 | O3: ='Raw Financial Data'!P4/'Raw Financial Data'!I4 -> 371.54217
E4: 0.09225489 | F4: 0.15750619 | G4: ='Raw Financial Data'!F5/'Raw Financial Data'!G5 -> 0.11697936 | H4: ='Raw Financial Data'!I5/'Raw Financial Data'!M5 -> 0.00079055537 | I4: ='Raw Financial Data'!D5/'Raw Financial Data'!N5 -> 118.15031 | J4: ='Raw Financial Data'!I5/'Raw Financial Data'!G5 -> 0.00058714304 | K4: ='Raw Financial Data'!J5/'Raw Financial Data'!K5 -> 0.8721476 | L4: =('Raw Financial Data'!J5-'Raw Financial Data'!L5)/'Raw Financial Data'!K5 -> 0.66722539 | M4: ='Raw Financial Data'!C5/'Raw Financial Data'!G5 -> 1.2680017 | N4: 22.382624 | O4: ='Raw Financial Data'!P5/'Raw Financial Data'!I5 -> 248.16987
E5: 0.091669506 | F5: 0.15066724 | G5: ='Raw Financial Data'!F6/'Raw Financial Data'!G6 -> 0.10987397 | H5: ='Raw Financial Data'!I6/'Raw Financial Data'!M6 -> 0.00060889506 | I5: ='Raw Financial Data'!D6/'Raw Financial Data'!N6 -> 130.90834 | J5: ='Raw Financial Data'!I6/'Raw Financial Data'!G6 -> 0.00044403627 | K5: ='Raw Financial Data'!J6/'Raw Financial Data'!K6 -> 0.96577419 | L5: =('Raw Financial Data'!J6-'Raw Financial Data'!L6)/'Raw Financial Data'!K6 -> 0.73963462 | M5: ='Raw Financial Data'!C6/'Raw Financial Data'!G6 -> 1.198588 | N5: 19.098035 | O5: ='Raw Financial Data'!P6/'Raw Financial Data'!I6 -> 275.36177 | P5: =(('Raw Financial Data'!C6/'Raw Financial Data'!C3)^(1/3)) - 1 -> 0.20574586
E6: -0.09442533 | F6: -0.47487621 | G6: ='Raw Financial Data'!F7/'Raw Financial Data'!G7 -> -0.094294736 | H6: ='Raw Financial Data'!I7/'Raw Financial Data'!M7 -> 1.1692027 | I6: ='Raw Financial Data'!D7/'Raw Financial Data'!N7 -> -0.35111312 | J6: ='Raw Financial Data'!I7/'Raw Financial Data'!G7 -> 0.23216506 | K6: ='Raw Financial Data'!J7/'Raw Financial Data'!K7 -> 0.8485724 | L6: =('Raw Financial Data'!J7-'Raw Financial Data'!L7)/'Raw Financial Data'!K7 -> 0.58035832 | M6: ='Raw Financial Data'!C7/'Raw Financial Data'!G7 -> 0.99861696 | N6: 5.8722329 | O6: ='Raw Financial Data'!P7/'Raw Financial Data'!I7 -> 0.26616561
E7: -0.040627695 | F7: -0.23430127 | G7: ='Raw Financial Data'!F8/'Raw Financial Data'!G8 -> -0.034770006 | H7: ='Raw Financial Data'!I8/'Raw Financial Data'!M8 -> 2.124037 | I7: ='Raw Financial Data'!D8/'Raw Financial Data'!N8 -> 2.9150073 | J7: ='Raw Financial Data'!I8/'Raw Financial Data'!G8 -> 0.31520434 | K7: ='Raw Financial Data'!J8/'Raw Financial Data'!K8 -> 0.97541013 | L7: =('Raw Financial Data'!J8-'Raw Financial Data'!L8)/'Raw Financial Data'!K8 -> 0.74153913 | M7: ='Raw Financial Data'!C8/'Raw Financial Data'!G8 -> 0.85582029 | N7: 6.0238392 | O7: ='Raw Financial Data'!P8/'Raw Financial Data'!I8 -> 0.13770351
E8: 0.0068418419 | F8: 0.045899477 | G8: ='Raw Financial Data'!F9/'Raw Financial Data'!G9 -> 0.0072138466 | H8: ='Raw Financial Data'!I9/'Raw Financial Data'!M9 -> 1.8301368 | I8: ='Raw Financial Data'!D9/'Raw Financial Data'!N9 -> 3.763126 | J8: ='Raw Financial Data'!I9/'Raw Financial Data'!G9 -> 0.28763566 | K8: ='Raw Financial Data'!J9/'Raw Financial Data'!K9 -> 0.97209111 | L8: =('Raw Financial Data'!J9-'Raw Financial Data'!L9)/'Raw Financial Data'!K9 -> 0.70919947 | M8: ='Raw Financial Data'!C9/'Raw Financial Data'!G9 -> 1.054372 | N8: 7.0377451 | O8: ='Raw Financial Data'!P9/'Raw Financial Data'!I9 -> 0.36761302
E9: 0.071297682 | F9: 0.33728275 | G9: ='Raw Financial Data'!F10/'Raw Financial Data'!G10 -> 0.084972167 | H9: ='Raw Financial Data'!I10/'Raw Financial Data'!M10 -> 0.74998389 | I9: ='Raw Financial Data'!D10/'Raw Financial Data'!N10 -> 8.2454569 | J9: ='Raw Financial Data'!I10/'Raw Financial Data'!G10 -> 0.18894461 | K9: ='Raw Financial Data'!J10/'Raw Financial Data'!K10 -> 0.96991061 | L9: =('Raw Financial Data'!J10-'Raw Financial Data'!L10)/'Raw Financial Data'!K10 -> 0.69465948 | M9: ='Raw Financial Data'!C10/'Raw Financial Data'!G10 -> 1.1917942 | N9: 7.1942129 | O9: ='Raw Financial Data'!P10/'Raw Financial Data'!I10 -> 0.97272949
E10: 0.061544517 | F10: 0.22671359 | G10: ='Raw Financial Data'!F11/'Raw Financial Data'!G11 -> 0.073824916 | H10: ='Raw Financial Data'!I11/'Raw Financial Data'!M11 -> 0.38987732 | I10: ='Raw Financial Data'!D11/'Raw Financial Data'!N11 -> 13.179225 | J10: ='Raw Financial Data'!I11/'Raw Financial Data'!G11 -> 0.12695604 | K10: ='Raw Financial Data'!J11/'Raw Financial Data'!K11 -> 0.96184997 | L10: =('Raw Financial Data'!J11-'Raw Financial Data'!L11)/'Raw Financial Data'!K11 -> 0.67826546 | M10: ='Raw Financial Data'!C11/'Raw Financial Data'!G11 -> 1.1995368 | N10: 6.7151288 | O10: ='Raw Financial Data'!P11/'Raw Financial Data'!I11 -> 1.3184981 | P10: =(('Raw Financial Data'!C11/'Raw Financial Data'!C8)^(1/3)) - 1 -> 0.17099417
E11: 0.049335037 | F11: 0.10995081 | G11: ='Raw Financial Data'!F12/'Raw Financial Data'!G12 -> 0.032834048 | H11: ='Raw Financial Data'!I12/'Raw Financial Data'!M12 -> 0.90034312 | I11: ='Raw Financial Data'!D12/'Raw Financial Data'!N12 -> 3.5613849 | J11: ='Raw Financial Data'!I12/'Raw Financial Data'!G12 -> 0.26886485 | K11: ='Raw Financial Data'!J12/'Raw Financial Data'!K12 -> 1.1842149 | L11: =('Raw Financial Data'!J12-'Raw Financial Data'!L12)/'Raw Financial Data'!K12 -> 0.97605415 | M11: ='Raw Financial Data'!C12/'Raw Financial Data'!G12 -> 0.66553204 | N11: 6.0606074 | O11: ='Raw Financial Data'!P12/'Raw Financial Data'!I12 -> -0.099877614
E12: 0.070311656 | F12: 0.11574641 | G12: ='Raw Financial Data'!F13/'Raw Financial Data'!G13 -> 0.038154055 | H12: ='Raw Financial Data'!I13/'Raw Financial Data'!M13 -> 0.898502 | I12: ='Raw Financial Data'!D13/'Raw Financial Data'!N13 -> 3.5645958 | J12: ='Raw Financial Data'!I13/'Raw Financial Data'!G13 -> 0.2961776 | K12: ='Raw Financial Data'!J13/'Raw Financial Data'!K13 -> 1.3350547 | L12: =('Raw Financial Data'!J13-'Raw Financial Data'!L13)/'Raw Financial Data'!K13 -> 1.1290472 | M12: ='Raw Financial Data'!C13/'Raw Financial Data'!G13 -> 0.54264197 | N12: 5.3116433 | O12: ='Raw Financial Data'!P13/'Raw Financial Data'!I13 -> 0.18111992
E13: 0.080974603 | F13: 0.15326739 | G13: ='Raw Financial Data'!F14/'Raw Financial Data'!G14 -> 0.050329658 | H13: ='Raw Financial Data'!I14/'Raw Financial Data'!M14 -> 0.86326876 | I13: ='Raw Financial Data'!D14/'Raw Financial Data'!N14 -> 4.1591746 | J13: ='Raw Financial Data'!I14/'Raw Financial Data'!G14 -> 0.28347857 | K13: ='Raw Financial Data'!J14/'Raw Financial Data'!K14 -> 1.2939388 | L13: =('Raw Financial Data'!J14-'Raw Financial Data'!L14)/'Raw Financial Data'!K14 -> 1.0551302 | M13: ='Raw Financial Data'!C14/'Raw Financial Data'!G14 -> 0.62154868 | N13: 6.0826641 | O13: ='Raw Financial Data'!P14/'Raw Financial Data'!I14 -> -0.12215565
E14: 0.079146981 | F14: 0.14168853 | G14: ='Raw Financial Data'!F15/'Raw Financial Data'!G15 -> 0.048008506 | H14: ='Raw Financial Data'!I15/'Raw Financial Data'!M15 -> 0.88686862 | I14: ='Raw Financial Data'!D15/'Raw Financial Data'!N15 -> 3.7645552 | J14: ='Raw Financial Data'!I15/'Raw Financial Data'!G15 -> 0.30049884 | K14: ='Raw Financial Data'!J15/'Raw Financial Data'!K15 -> 1.3007452 | L14: =('Raw Financial Data'!J15-'Raw Financial Data'!L15)/'Raw Financial Data'!K15 -> 1.0546626 | M14: ='Raw Financial Data'!C15/'Raw Financial Data'!G15 -> 0.60657407 | N14: 5.442005 | O14: ='Raw Financial Data'!P15/'Raw Financial Data'!I15 -> -0.079819394
E15: 0.079354056 | F15: 0.13876405 | G15: ='Raw Financial Data'!F16/'Raw Financial Data'!G16 -> 0.046842332 | H15: ='Raw Financial Data'!I16/'Raw Financial Data'!M16 -> 0.88949685 | I15: ='Raw Financial Data'!D16/'Raw Financial Data'!N16 -> 3.7691501 | J15: ='Raw Financial Data'!I16/'Raw Financial Data'!G16 -> 0.30026586 | K15: ='Raw Financial Data'!J16/'Raw Financial Data'!K16 -> 1.4013558 | L15: =('Raw Financial Data'!J16-'Raw Financial Data'!L16)/'Raw Financial Data'!K16 -> 1.1762619 | M15: ='Raw Financial Data'!C16/'Raw Financial Data'!G16 -> 0.59029537 | N15: 5.5349201 | O15: ='Raw Financial Data'!P16/'Raw Financial Data'!I16 -> 0.038319405 | P15: =(('Raw Financial Data'!C16/'Raw Financial Data'!C12)^(1/3))-1 -> 0.14781331
E16: 0.061507698 | F16: 0.21166645 | G16: ='Raw Financial Data'!F17/'Raw Financial Data'!G17 -> 0.053128898 | H16: ='Raw Financial Data'!I17/'Raw Financial Data'!M17 -> 1.3247253 | I16: ='Raw Financial Data'!D17/'Raw Financial Data'!N17 -> 3.3612871 | J16: ='Raw Financial Data'!I17/'Raw Financial Data'!G17 -> 0.33250992 | K16: ='Raw Financial Data'!J17/'Raw Financial Data'!K17 -> 1.0764274 | L16: =('Raw Financial Data'!J17-'Raw Financial Data'!L17)/'Raw Financial Data'!K17 -> 0.87568045 | M16: ='Raw Financial Data'!C17/'Raw Financial Data'!G17 -> 0.8637764 | N16: 8.2782331 | O16: ='Raw Financial Data'!P17/'Raw Financial Data'!I17 -> -0.2879009
E17: -0.013410222 | F17: -0.041746603 | G17: ='Raw Financial Data'!F18/'Raw Financial Data'!G18 -> -0.0082299738 | H17: ='Raw Financial Data'!I18/'Raw Financial Data'!M18 -> 1.7994857 | I17: ='Raw Financial Data'!D18/'Raw Financial Data'!N18 -> 1.3565287 | J17: ='Raw Financial Data'!I18/'Raw Financial Data'!G18 -> 0.3547527 | K17: ='Raw Financial Data'!J18/'Raw Financial Data'!K18 -> 1.0012033 | L17: =('Raw Financial Data'!J18-'Raw Financial Data'!L18)/'Raw Financial Data'!K18 -> 0.86473122 | M17: ='Raw Financial Data'!C18/'Raw Financial Data'!G18 -> 0.61370897 | N17: 8.0262542 | O17: ='Raw Financial Data'!P18/'Raw Financial Data'!I18 -> 0.18402018
E18: 0.029146577 | F18: 0.11473989 | G18: ='Raw Financial Data'!F19/'Raw Financial Data'!G19 -> 0.022646792 | H18: ='Raw Financial Data'!I19/'Raw Financial Data'!M19 -> 1.8240252 | I18: ='Raw Financial Data'!D19/'Raw Financial Data'!N19 -> 2.511894 | J18: ='Raw Financial Data'!I19/'Raw Financial Data'!G19 -> 0.3600171 | K18: ='Raw Financial Data'!J19/'Raw Financial Data'!K19 -> 1.0796479 | L18: =('Raw Financial Data'!J19-'Raw Financial Data'!L19)/'Raw Financial Data'!K19 -> 0.92643315 | M18: ='Raw Financial Data'!C19/'Raw Financial Data'!G19 -> 0.77699662 | N18: 11.041746 | O18: ='Raw Financial Data'!P19/'Raw Financial Data'!I19 -> -0.22848359
E19: 0.053104453 | F19: 0.21020789 | G19: ='Raw Financial Data'!F20/'Raw Financial Data'!G20 -> 0.036741119 | H19: ='Raw Financial Data'!I20/'Raw Financial Data'!M20 -> 2.2723531 | I19: ='Raw Financial Data'!D20/'Raw Financial Data'!N20 -> 2.6877727 | J19: ='Raw Financial Data'!I20/'Raw Financial Data'!G20 -> 0.39717252 | K19: ='Raw Financial Data'!J20/'Raw Financial Data'!K20 -> 1.0917023 | L19: =('Raw Financial Data'!J20-'Raw Financial Data'!L20)/'Raw Financial Data'!K20 -> 0.94147661 | M19: ='Raw Financial Data'!C20/'Raw Financial Data'!G20 -> 0.69186514 | N19: 9.0799013 | O19: ='Raw Financial Data'!P20/'Raw Financial Data'!I20 -> -0.23309862
E20: 0.062165578 | F20: 0.1960762 | G20: ='Raw Financial Data'!F21/'Raw Financial Data'!G21 -> 0.038098597 | H20: ='Raw Financial Data'!I21/'Raw Financial Data'!M21 -> 2.307898 | I20: ='Raw Financial Data'!D21/'Raw Financial Data'!N21 -> 2.4459736 | J20: ='Raw Financial Data'!I21/'Raw Financial Data'!G21 -> 0.44843623 | K20: ='Raw Financial Data'!J21/'Raw Financial Data'!K21 -> 1.2895803 | L20: =('Raw Financial Data'!J21-'Raw Financial Data'!L21)/'Raw Financial Data'!K21 -> 1.1394537 | M20: ='Raw Financial Data'!C21/'Raw Financial Data'!G21 -> 0.61285679 | N20: 8.500147 | O20: ='Raw Financial Data'!P21/'Raw Financial Data'!I21 -> 0.0035131502 | P20: =(('Raw Financial Data'!C21/'Raw Financial Data'!C17)^(1/3) - 1) -> 0.13928835
E21: 0.20980679 | F21: 0.24697827 | G21: ='Raw Financial Data'!F22/'Raw Financial Data'!G22 -> 0.19344541 | H21: ='Raw Financial Data'!I22/'Raw Financial Data'!M22 -> 0 | I21: ='Raw Financial Data'!D22/'Raw Financial Data'!N22 -> 491.80082 | J21: ='Raw Financial Data'!I22/'Raw Financial Data'!G22 -> 0 | K21: ='Raw Financial Data'!J22/'Raw Financial Data'!K22 -> 2.104573 | L21: =('Raw Financial Data'!J22-'Raw Financial Data'!L22)/'Raw Financial Data'!K22 -> 1.8026702 | M21: ='Raw Financial Data'!C22/'Raw Financial Data'!G22 -> 0.92201693 | N21: 9.5346238 | O21: ='Raw Financial Data'!P22/'Raw Financial Data'!I22 -> #DIV/0!
E22: 0.15525799 | F22: 0.13297906 | G22: ='Raw Financial Data'!F23/'Raw Financial Data'!G23 -> 0.10387966 | H22: ='Raw Financial Data'!I23/'Raw Financial Data'!M23 -> 0.0028013959 | I22: ='Raw Financial Data'!D23/'Raw Financial Data'!N23 -> 142.34398 | J22: ='Raw Financial Data'!I23/'Raw Financial Data'!G23 -> 0.002188375 | K22: ='Raw Financial Data'!J23/'Raw Financial Data'!K23 -> 1.9421436 | L22: =('Raw Financial Data'!J23-'Raw Financial Data'!L23)/'Raw Financial Data'!K23 -> 1.5507661 | M22: ='Raw Financial Data'!C23/'Raw Financial Data'!G23 -> 0.66907768 | N22: 6.1675026 | O22: ='Raw Financial Data'!P23/'Raw Financial Data'!I23 -> 43.234428
E23: 0.18980281 | F23: 0.19438863 | G23: ='Raw Financial Data'!F24/'Raw Financial Data'!G24 -> 0.15178637 | H23: ='Raw Financial Data'!I24/'Raw Financial Data'!M24 -> 0.0087223187 | I23: ='Raw Financial Data'!D24/'Raw Financial Data'!N24 -> 155.38401 | J23: ='Raw Financial Data'!I24/'Raw Financial Data'!G24 -> 0.006810733 | K23: ='Raw Financial Data'!J24/'Raw Financial Data'!K24 -> 1.1387043 | L23: =('Raw Financial Data'!J24-'Raw Financial Data'!L24)/'Raw Financial Data'!K24 -> 0.74346283 | M23: ='Raw Financial Data'!C24/'Raw Financial Data'!G24 -> 0.79970559 | N23: 6.9610577 | O23: ='Raw Financial Data'!P24/'Raw Financial Data'!I24 -> 21.588222
E24: 0.2215476 | F24: 0.22171751 | G24: ='Raw Financial Data'!F25/'Raw Financial Data'!G25 -> 0.17309053 | H24: ='Raw Financial Data'!I25/'Raw Financial Data'!M25 -> 0.015041952 | I24: ='Raw Financial Data'!D25/'Raw Financial Data'!N25 -> 114.98624 | J24: ='Raw Financial Data'!I25/'Raw Financial Data'!G25 -> 0.011742958 | K24: ='Raw Financial Data'!J25/'Raw Financial Data'!K25 -> 1.1536568 | L24: =('Raw Financial Data'!J25-'Raw Financial Data'!L25)/'Raw Financial Data'!K25 -> 0.76191707 | M24: ='Raw Financial Data'!C25/'Raw Financial Data'!G25 -> 0.78127919 | N24: 7.0651008 | O24: ='Raw Financial Data'!P25/'Raw Financial Data'!I25 -> 13.718354
E25: 0.22679887 | F25: 0.22231081 | G25: ='Raw Financial Data'!F26/'Raw Financial Data'!G26 -> 0.17422421 | H25: ='Raw Financial Data'!I26/'Raw Financial Data'!M26 -> 0.01447046 | I25: ='Raw Financial Data'!D26/'Raw Financial Data'!N26 -> 123.60582 | J25: ='Raw Financial Data'!I26/'Raw Financial Data'!G26 -> 0.011340449 | K25: ='Raw Financial Data'!J26/'Raw Financial Data'!K26 -> 1.63022 | L25: =('Raw Financial Data'!J26-'Raw Financial Data'!L26)/'Raw Financial Data'!K26 -> 1.2636399 | M25: ='Raw Financial Data'!C26/'Raw Financial Data'!G26 -> 0.76818816 | N25: 9.4650452 | O25: ='Raw Financial Data'!P26/'Raw Financial Data'!I26 -> 12.91469 | P25: =(('Raw Financial Data'!C26/'Raw Financial Data'!C22)^(1/3)) -1 -> 0.25746334
E26: 0.15211551 | F26: 0.21208781 | G26: ='Raw Financial Data'!F27/'Raw Financial Data'!G27 -> 0.17089339 | H26: ='Raw Financial Data'!I27/'Raw Financial Data'!M27 -> 0.0053594286 | I26: ='Raw Financial Data'!D27/'Raw Financial Data'!N27 -> 1612.8906 | J26: ='Raw Financial Data'!I27/'Raw Financial Data'!G27 -> 0.0043184515 | K26: ='Raw Financial Data'!J27/'Raw Financial Data'!K27 -> 1.4512678 | L26: =('Raw Financial Data'!J27-'Raw Financial Data'!L27)/'Raw Financial Data'!K27 -> 1.2539856 | M26: ='Raw Financial Data'!C27/'Raw Financial Data'!G27 -> 1.1234449 | N26: 24.155755 | O26: ='Raw Financial Data'!P27/'Raw Financial Data'!I27 -> 19.971571
E27: 0.17211134 | F27: 0.20649498 | G27: ='Raw Financial Data'!F28/'Raw Financial Data'!G28 -> 0.17560973 | H27: ='Raw Financial Data'!I28/'Raw Financial Data'!M28 -> 0.0041115672 | I27: ='Raw Financial Data'!D28/'Raw Financial Data'!N28 -> 915.71594 | J27: ='Raw Financial Data'!I28/'Raw Financial Data'!G28 -> 0.0034966041 | K27: ='Raw Financial Data'!J28/'Raw Financial Data'!K28 -> 2.2108585 | L27: =('Raw Financial Data'!J28-'Raw Financial Data'!L28)/'Raw Financial Data'!K28 -> 1.9484057 | M27: ='Raw Financial Data'!C28/'Raw Financial Data'!G28 -> 1.0203263 | N27: 20.81467 | O27: ='Raw Financial Data'!P28/'Raw Financial Data'!I28 -> 34.187587
E28: 0.15875982 | F28: 0.20639953 | G28: ='Raw Financial Data'!F29/'Raw Financial Data'!G29 -> 0.17247645 | H28: ='Raw Financial Data'!I29/'Raw Financial Data'!M29 -> 0.0042310437 | I28: ='Raw Financial Data'!D29/'Raw Financial Data'!N29 -> 206.71577 | J28: ='Raw Financial Data'!I29/'Raw Financial Data'!G29 -> 0.0035356446 | K28: ='Raw Financial Data'!J29/'Raw Financial Data'!K29 -> 1.8309365 | L28: =('Raw Financial Data'!J29-'Raw Financial Data'!L29)/'Raw Financial Data'!K29 -> 1.5342893 | M28: ='Raw Financial Data'!C29/'Raw Financial Data'!G29 -> 1.0863986 | N28: 19.919866 | O28: ='Raw Financial Data'!P29/'Raw Financial Data'!I29 -> 42.481043
E29: 0.16550508 | F29: 0.26614627 | G29: ='Raw Financial Data'!F30/'Raw Financial Data'!G30 -> 0.19592062 | H29: ='Raw Financial Data'!I30/'Raw Financial Data'!M30 -> 0.026212243 | I29: ='Raw Financial Data'!D30/'Raw Financial Data'!N30 -> 173.37922 | J29: ='Raw Financial Data'!I30/'Raw Financial Data'!G30 -> 0.019295852 | K29: ='Raw Financial Data'!J30/'Raw Financial Data'!K30 -> 1.2977749 | L29: =('Raw Financial Data'!J30-'Raw Financial Data'!L30)/'Raw Financial Data'!K30 -> 1.1120189 | M29: ='Raw Financial Data'!C30/'Raw Financial Data'!G30 -> 1.1837741 | N29: 20.751167 | O29: ='Raw Financial Data'!P30/'Raw Financial Data'!I30 -> 8.6385921
E30: 0.1396012 | F30: 0.20815545 | G30: ='Raw Financial Data'!F31/'Raw Financial Data'!G31 -> 0.1353676 | H30: ='Raw Financial Data'!I31/'Raw Financial Data'!M31 -> 0.17648766 | I30: ='Raw Financial Data'!D31/'Raw Financial Data'!N31 -> 28.353458 | J30: ='Raw Financial Data'!I31/'Raw Financial Data'!G31 -> 0.11477341 | K30: ='Raw Financial Data'!J31/'Raw Financial Data'!K31 -> 1.6787162 | L30: =('Raw Financial Data'!J31-'Raw Financial Data'!L31)/'Raw Financial Data'!K31 -> 1.4993832 | M30: ='Raw Financial Data'!C31/'Raw Financial Data'!G31 -> 0.96967358 | N30: 19.826038 | O30: ='Raw Financial Data'!P31/'Raw Financial Data'!I31 -> -0.22632593 | P30: =(('Raw Financial Data'!C31/'Raw Financial Data'!C27)^(1/3)) -1 -> 0.17439233
E31: 0.099200969 | F31: 0.26019603 | G31: ='Raw Financial Data'!F32/'Raw Financial Data'!G32 -> 0.18612316 | H31: ='Raw Financial Data'!I32/'Raw Financial Data'!M32 -> 0.009431482 | I31: ='Raw Financial Data'!D32/'Raw Financial Data'!N32 -> 155.08123 | J31: ='Raw Financial Data'!I32/'Raw Financial Data'!G32 -> 0.0067465181 | K31: ='Raw Financial Data'!J32/'Raw Financial Data'!K32 -> 1.9081122 | L31: =('Raw Financial Data'!J32-'Raw Financial Data'!L32)/'Raw Financial Data'!K32 -> 1.6247193 | M31: ='Raw Financial Data'!C32/'Raw Financial Data'!G32 -> 1.8762232 | N31: 22.106832 | O31: ='Raw Financial Data'!P32/'Raw Financial Data'!I32 -> 8.2688241
E32: 0.076956676 | F32: 0.14485298 | G32: ='Raw Financial Data'!F33/'Raw Financial Data'!G33 -> 0.10307144 | H32: ='Raw Financial Data'!I33/'Raw Financial Data'!M33 -> 0.015735212 | I32: ='Raw Financial Data'!D33/'Raw Financial Data'!N33 -> 71.576836 | J32: ='Raw Financial Data'!I33/'Raw Financial Data'!G33 -> 0.011196531 | K32: ='Raw Financial Data'!J33/'Raw Financial Data'!K33 -> 1.9160799 | L32: =('Raw Financial Data'!J33-'Raw Financial Data'!L33)/'Raw Financial Data'!K33 -> 1.6492244 | M32: ='Raw Financial Data'!C33/'Raw Financial Data'!G33 -> 1.3393437 | N32: 15.618741 | O32: ='Raw Financial Data'!P33/'Raw Financial Data'!I33 -> 8.35863
E33: 0.08090756 | F33: 0.16745259 | G33: ='Raw Financial Data'!F34/'Raw Financial Data'!G34 -> 0.11748783 | H33: ='Raw Financial Data'!I34/'Raw Financial Data'!M34 -> 0.014287902 | I33: ='Raw Financial Data'!D34/'Raw Financial Data'!N34 -> 44.487891 | J33: ='Raw Financial Data'!I34/'Raw Financial Data'!G34 -> 0.010024656 | K33: ='Raw Financial Data'!J34/'Raw Financial Data'!K34 -> 1.5692543 | L33: =('Raw Financial Data'!J34-'Raw Financial Data'!L34)/'Raw Financial Data'!K34 -> 1.2771371 | M33: ='Raw Financial Data'!C34/'Raw Financial Data'!G34 -> 1.4521243 | N33: 16.397628 | O33: ='Raw Financial Data'!P34/'Raw Financial Data'!I34 -> 10.901902
E34: 0.096907965 | F34: 0.20997591 | G34: ='Raw Financial Data'!F35/'Raw Financial Data'!G35 -> 0.14319046 | H34: ='Raw Financial Data'!I35/'Raw Financial Data'!M35 -> 0.011165394 | I34: ='Raw Financial Data'!D35/'Raw Financial Data'!N35 -> 77.56881 | J34: ='Raw Financial Data'!I35/'Raw Financial Data'!G35 -> 0.0076141016 | K34: ='Raw Financial Data'!J35/'Raw Financial Data'!K35 -> 1.4635228 | L34: =('Raw Financial Data'!J35-'Raw Financial Data'!L35)/'Raw Financial Data'!K35 -> 1.2144013 | M34: ='Raw Financial Data'!C35/'Raw Financial Data'!G35 -> 1.4775923 | N34: 15.985474 | O34: ='Raw Financial Data'!P35/'Raw Financial Data'!I35 -> 24.722895
E35: 0.10433026 | F35: 0.22564727 | G35: ='Raw Financial Data'!F36/'Raw Financial Data'!G36 -> 0.1542244 | H35: ='Raw Financial Data'!I36/'Raw Financial Data'!M36 -> 0.010111786 | I35: ='Raw Financial Data'!D36/'Raw Financial Data'!N36 -> 96.656759 | J35: ='Raw Financial Data'!I36/'Raw Financial Data'!G36 -> 0.0069111585 | K35: ='Raw Financial Data'!J36/'Raw Financial Data'!K36 -> 1.7969403 | L35: =('Raw Financial Data'!J36-'Raw Financial Data'!L36)/'Raw Financial Data'!K36 -> 1.5276325 | M35: ='Raw Financial Data'!C36/'Raw Financial Data'!G36 -> 1.4782327 | N35: 15.900383 | O35: ='Raw Financial Data'!P36/'Raw Financial Data'!I36 -> 21.901993 | P35: =(('Raw Financial Data'!C36/'Raw Financial Data'!C32)^(1/3)) -1 -> 0.065249913
E36: 0.034906894 | F36: 0.20628875 | G36: ='Raw Financial Data'!F37/'Raw Financial Data'!G37 -> 0.042204679 | H36: ='Raw Financial Data'!I37/'Raw Financial Data'!M37 -> 1.437133 | I36: ='Raw Financial Data'!D37/'Raw Financial Data'!N37 -> 3.2981007 | J36: ='Raw Financial Data'!I37/'Raw Financial Data'!G37 -> 0.29402347 | K36: ='Raw Financial Data'!J37/'Raw Financial Data'!K37 -> 1.0179455 | L36: =('Raw Financial Data'!J37-'Raw Financial Data'!L37)/'Raw Financial Data'!K37 -> 0.86014424 | M36: ='Raw Financial Data'!C37/'Raw Financial Data'!G37 -> 1.2090643 | N36: 12.07988 | O36: ='Raw Financial Data'!P37/'Raw Financial Data'!I37 -> -0.18698515
E37: 0.17237005 | F37: 0.14977607 | G37: ='Raw Financial Data'!F38/'Raw Financial Data'!G38 -> 0.02811461 | H37: ='Raw Financial Data'!I38/'Raw Financial Data'!M38 -> 1.5255897 | I37: ='Raw Financial Data'!D38/'Raw Financial Data'!N38 -> 2.9247091 | J37: ='Raw Financial Data'!I38/'Raw Financial Data'!G38 -> 0.2863699 | K37: ='Raw Financial Data'!J38/'Raw Financial Data'!K38 -> 0.92674759 | L37: =('Raw Financial Data'!J38-'Raw Financial Data'!L38)/'Raw Financial Data'!K38 -> 0.80864572 | M37: ='Raw Financial Data'!C38/'Raw Financial Data'!G38 -> 0.16310612 | N37: 11.42814 | O37: ='Raw Financial Data'!P38/'Raw Financial Data'!I38 -> -0.20433607
E38: 0.041376134 | F38: 0.22482297 | G38: ='Raw Financial Data'!F39/'Raw Financial Data'!G39 -> 0.037935402 | H38: ='Raw Financial Data'!I39/'Raw Financial Data'!M39 -> 1.6290752 | I38: ='Raw Financial Data'!D39/'Raw Financial Data'!N39 -> 3.0432125 | J38: ='Raw Financial Data'!I39/'Raw Financial Data'!G39 -> 0.27488127 | K38: ='Raw Financial Data'!J39/'Raw Financial Data'!K39 -> 0.88493134 | L38: =('Raw Financial Data'!J39-'Raw Financial Data'!L39)/'Raw Financial Data'!K39 -> 0.78495007 | M38: ='Raw Financial Data'!C39/'Raw Financial Data'!G39 -> 0.91684259 | N38: 13.472955 | O38: ='Raw Financial Data'!P39/'Raw Financial Data'!I39 -> -0.45752156
E39: 0.042964228 | F39: 0.22451675 | G39: ='Raw Financial Data'!F40/'Raw Financial Data'!G40 -> 0.040128736 | H39: ='Raw Financial Data'!I40/'Raw Financial Data'!M40 -> 1.7484766 | I39: ='Raw Financial Data'!D40/'Raw Financial Data'!N40 -> 2.9079742 | J39: ='Raw Financial Data'!I40/'Raw Financial Data'!G40 -> 0.3125119 | K39: ='Raw Financial Data'!J40/'Raw Financial Data'!K40 -> 1.02096 | L39: =('Raw Financial Data'!J40-'Raw Financial Data'!L40)/'Raw Financial Data'!K40 -> 0.91429063 | M39: ='Raw Financial Data'!C40/'Raw Financial Data'!G40 -> 0.93400343 | N39: 13.546945 | O39: ='Raw Financial Data'!P40/'Raw Financial Data'!I40 -> -0.095383385
E40: 0.050591466 | F40: 0.23676086 | G40: ='Raw Financial Data'!F41/'Raw Financial Data'!G41 -> 0.046915388 | H40: ='Raw Financial Data'!I41/'Raw Financial Data'!M41 -> 1.5551885 | I40: ='Raw Financial Data'!D41/'Raw Financial Data'!N41 -> 3.1883769 | J40: ='Raw Financial Data'!I41/'Raw Financial Data'!G41 -> 0.30816864 | K40: ='Raw Financial Data'!J41/'Raw Financial Data'!K41 -> 1.1212896 | L40: =('Raw Financial Data'!J41-'Raw Financial Data'!L41)/'Raw Financial Data'!K41 -> 1.0170078 | M40: ='Raw Financial Data'!C41/'Raw Financial Data'!G41 -> 0.92733798 | N40: 13.077256 | O40: ='Raw Financial Data'!P41/'Raw Financial Data'!I41 -> 0.23854524 | P40: =(('Raw Financial Data'!C41/'Raw Financial Data'!C37)^(1/3)) - 1 -> 0.29840893
...
